Workbook
Name costerecursosbaselineactual: 'Cost Overview'!$G$8
Name costerecursostotalplanificado: costerecursosbaselineactual-'Cost Planning'!$J$5
Name FECHA: 'Project Infor'!$D$6
Name FIN: 'Project Infor'!$C$9
Name Inicio: 'Project Infor'!$C$8
Name margendirectobaselineactual: 'Cost Overview'!$F$8-'Cost Overview'!$M$8
Name margendirectofinal: margendirectobaselineactual+'Cost Planning'!$J$5+'Cost Planning'!$E$47+'Cost Planning'!$E$48+'Cost Planning'!$J$50+'Cost Planning'!$J$64
Name pedidobaselineactual: 'Cost Overview'!$F$8
Name UTILIZACION: 0.93

Sheet Project Infor
B3: CORE (COst REport) - AT
B5: Fecha Actual | C5: 44331
B6: Fecha Reporting | C6: =DATE(IF(EXACT(MONTH(EDATE(C5,0)),"12"),YEAR(C5)+1,YEAR(C5)),MONTH(EDATE(C5,1)),1) -> 44348 | D6: =DATE(YEAR(C6),MONTH(C6),1) -> 44348
B8: Fecha de Inicio CORE | C8: 44287
B9: Fecha Fin CORE | C9: 44561
B10: WBS-Element | C10: ZEZ-AT00001-1001
B11: Descripción | C11: Asistencia técnica para desarrollo Java/.Net/…
B12: Práctica principal
B13: Otras prácticas relacionadas
C15: CÓDIGO | D15: DESCRIPCIÓN
B16: Cliente
B18: Contrato / Expediente
B19: Pedido (Order)
C21: COD EMPLEADO | D21: NOMBRE Y APELLIDOS
B22: Project Manager
B23: Practice Leader
B24: Sales Manager
B26: PRESUPUESTO INICIAL (PPO)
B28: Pedido
B29: Horas estimadas
B30: Coste Recursos
B31: Riegos
B32: Garantía
B33: Gastos
B34: Compras
B35: Coste Directo | C35: =SUM(C30:C34) -> 0
B37: Margen Directo | C37: =IF(C28=0,0,(C28-C35)/C28) -> 0
B38: Margen Bruto | C38: =IF(C28=0,0,(C28-(SUM(C30,C31,C32)/UTILIZACION)-SUM(C34,C33))/C28) -> 0
B40: Comentarios adicionales Presupuesto inicial
B43: PRESUPUESTO YA CONSUMIDO
B45: Venta incurrida
B46: Horas realizadas
B47: Coste Recursos incurrido
B48: Gastos incurridos
B49: Compras incurridas
B50: Coste Directo | C50: =SUM(C47:C49) -> 0
B52: Margen Directo (To Date) | C52: =IF(C45=0,0,(C45-C50)/C45) -> 0
B54: Facturación ya emitida
B56: Comentarios adicionales Presupuesto ya consumido
B60: Prácticas
...

Sheet Cost Overview
B2: WBS-Element | C2: ='Project Infor'!C10 -> ZEZ-AT00001-1001 | D2: ='Project Infor'!C11 -> Asistencia técnica para desarrollo Java/.Net/…
B5: BASELINE ACTUAL | U5: pneta | V5: operac | W5: coste r. | X5: reservas | Y5: gastos | Z5: compras | AA5: Venta
F6: PEDIDO IMPORTE NETO | G6: COSTE RECURSOS | H6: HORAS | I6: RIESGOS | J6: GARANTÍA | K6: GASTOS | L6: COMPRAS | M6: COSTE DIRECTO | N6: MARGEN DIRECTO | O6: MARGEN BRUTO
B7: PROYECCION DEL PROYECTO SIN REESTIMACIONES | F7: =SUM(F12,F36) -> 0 | G7: =SUM(G12,G36) -> 0 | H7: =SUM(H12,H36) -> 0 | I7: =SUM(I12,I36) -> 0 | J7: =SUM(J12,J36) -> 0 | K7: =SUM(K12,K36) -> 0 | L7: =SUM(L12,L36) -> 0 | M7: =SUM(G7,I7,J7,K7,L7) -> 0 | N7: =IF(F7=0,0,(F7-G7-J7-K7-I7-L7)/F7) -> 0 | O7: =IF(F7=0,0,(F7-G7/UTILIZACION-I7/UTILIZACION-J7/UTILIZACION-K7-L7)/F7) -> 0
B8: LINEA BASE ACTUAL - PROYECCION DEL PROYECTO FINAL | F8: =F7 -> 0 | G8: =G7+G37 -> 0 | H8: =H7+H37 -> 0 | I8: =I7+I37 -> 0 | J8: =J7+J37 -> 0 | K8: =K7+K37 -> 0 | L8: =L7+L37 -> 0 | M8: =M7+M37 -> 0 | N8: =IF(F8=0,0,(F8-G8-J8-K8-I8-L8)/F8) -> 0 | O8: =IF(F8=0,0,(F8-G8/UTILIZACION-I8/UTILIZACION-J8/UTILIZACION-K8-L8)/F8) -> 0 | P8: {=margendirectobaselineactual} -> 0
B10: BASELINE INICIAL | U10: pneta | V10: operac | W10: coste r. | X10: reservas | Y10: gastos | Z10: compras | AA10: Venta
C11: FECHA | D11: LÍNEA DE PEDIDO | E11: DESCRIPCIÓN | F11: IMPORTE NETO | G11: COSTE RECURSOS | H11: HORAS | I11: RIESGOS | J11: GARANTÍA | K11: GASTOS | L11: COMPRAS | M11: COSTE DIRECTO | N11: MARGEN DIRECTO | O11: MARGEN BRUTO
D12: 10 | E12: Apertura contrato | F12: ='Project Infor'!C28 -> 0 | G12: ='Project Infor'!C30 -> 0 | H12: ='Project Infor'!C29 -> 0 | I12: ='Project Infor'!C31 -> 0 | J12: ='Project Infor'!C32 -> 0 | K12: ='Project Infor'!C33 -> 0 | L12: ='Project Infor'!C34 -> 0 | M12: =SUM(G12,I12,J12,K12,L12) -> 0 | N12: =IF(F12=0,0,(F12-G12-J12-K12-I12-L12)/F12) -> 0 | O12: =IF(F12=0,0,(F12-G12/UTILIZACION-I12/UTILIZACION-J12/UTILIZACION-K12-L12)/F12) -> 0 | T12: *** Ocultar estos datos en la versión definitiva
B14: Cambios sobre la BASELINE INICIAL | U14: pneta | V14: operac | W14: coste r. | X14: reservas | Y14: gastos | Z14: compras | AA14: Venta
B15: TIPO CAMBIO | C15: FECHA | D15: LÍNEA DE PEDIDO | E15: DESCRIPCIÓN | F15: PEDIDO IMPORTE NETO | G15: COSTE RECURSOS | H15: HORAS | I15: RIESGOS | J15: GARANTÍA | K15: GASTOS | L15: COMPRAS | M15: COSTE DIRECTO | N15: MARGEN DIRECTO | O15: MARGEN BRUTO | P15: AUTORIZADO POR CCO | R15: DATOS ADICIONALES AMPLIACION
M16: =SUM(G16,I16,J16,K16,L16) -> 0 | N16: =IF(F16=0,0,(F16-G16-J16-K16-I16-L16)/F16) -> 0 | O16: =IF(F16=0,0,(F16-G16/UTILIZACION-I16/UTILIZACION-J16/UTILIZACION-K16-L16)/F16) -> 0 | R16: ej:otro cliente, PO asociada, … | T16: =IF(C16<>"",IF((YEAR(C16)&MONTH(C16))<(YEAR(Inicio)&MONTH(Inicio)),YEAR(Inicio)&MONTH(Inicio),YEAR(C16)&MONTH(C16)),YEAR(C16)&MONTH(C16)) -> 19001 | U16: =AA16-Y16-X16-W16 -> 0 | W16: =$G$12+SUM($G$16:G16) -> 0 | X16: =$I$12+SUM($I$16:I16)+$J$12+SUM($J$16:J16) -> 0 | Y16: =$K$12+SUM($K$16:K16) -> 0 | Z16: =$L$12+SUM($L$16:L16) -> 0 | AA16: =$F$12+SUM($F$16:F16) -> 0
M17: =SUM(G17,I17,J17,K17,L17) -> 0 | N17: =IF(F17=0,0,(F17-G17-J17-K17-I17-L17)/F17) -> 0 | O17: =IF(F17=0,0,(F17-G17/UTILIZACION-I17/UTILIZACION-J17/UTILIZACION-K17-L17)/F17) -> 0 | T17: =IF(C17<>"",IF((YEAR(C17)&MONTH(C17))<(YEAR(Inicio)&MONTH(Inicio)),YEAR(Inicio)&MONTH(Inicio),YEAR(C17)&MONTH(C17)),YEAR(C17)&MONTH(C17)) -> 19001 | U17: =AA17-Y17-X17-W17 -> 0 | W17: =$G$12+SUM($G$16:G17) -> 0 | X17: =$I$12+SUM($I$16:I17)+$J$12+SUM($J$16:J17) -> 0 | Y17: =$K$12+SUM($K$16:K17) -> 0 | Z17: =$L$12+SUM($L$16:L17) -> 0 | AA17: =$F$12+SUM($F$16:F17) -> 0
M18: =SUM(G18,I18,J18,K18,L18) -> 0 | N18: =IF(F18=0,0,(F18-G18-J18-K18-I18-L18)/F18) -> 0 | O18: =IF(F18=0,0,(F18-G18/UTILIZACION-I18/UTILIZACION-J18/UTILIZACION-K18-L18)/F18) -> 0 | T18: =IF(C18<>"",IF((YEAR(C18)&MONTH(C18))<(YEAR(Inicio)&MONTH(Inicio)),YEAR(Inicio)&MONTH(Inicio),YEAR(C18)&MONTH(C18)),YEAR(C18)&MONTH(C18)) -> 19001 | U18: =AA18-Y18-X18-W18 -> 0 | W18: =$G$12+SUM($G$16:G18) -> 0 | X18: =$I$12+SUM($I$16:I18)+$J$12+SUM($J$16:J18) -> 0 | Y18: =$K$12+SUM($K$16:K18) -> 0 | Z18: =$L$12+SUM($L$16:L18) -> 0 | AA18: =$F$12+SUM($F$16:F18) -> 0
M19: =SUM(G19,I19,J19,K19,L19) -> 0 | N19: =IF(F19=0,0,(F19-G19-J19-K19-I19-L19)/F19) -> 0 | O19: =IF(F19=0,0,(F19-G19/UTILIZACION-I19/UTILIZACION-J19/UTILIZACION-K19-L19)/F19) -> 0 | T19: =IF(C19<>"",IF((YEAR(C19)&MONTH(C19))<(YEAR(Inicio)&MONTH(Inicio)),YEAR(Inicio)&MONTH(Inicio),YEAR(C19)&MONTH(C19)),YEAR(C19)&MONTH(C19)) -> 19001 | U19: =AA19-Y19-X19-W19 -> 0 | W19: =$G$12+SUM($G$16:G19) -> 0 | X19: =$I$12+SUM($I$16:I19)+$J$12+SUM($J$16:J19) -> 0 | Y19: =$K$12+SUM($K$16:K19) -> 0 | Z19: =$L$12+SUM($L$16:L19) -> 0 | AA19: =$F$12+SUM($F$16:F19) -> 0
M20: =SUM(G20,I20,J20,K20,L20) -> 0 | N20: =IF(F20=0,0,(F20-G20-J20-K20-I20-L20)/F20) -> 0 | O20: =IF(F20=0,0,(F20-G20/UTILIZACION-I20/UTILIZACION-J20/UTILIZACION-K20-L20)/F20) -> 0 | T20: =IF(C20<>"",IF((YEAR(C20)&MONTH(C20))<(YEAR(Inicio)&MONTH(Inicio)),YEAR(Inicio)&MONTH(Inicio),YEAR(C20)&MONTH(C20)),YEAR(C20)&MONTH(C20)) -> 19001 | U20: =AA20-Y20-X20-W20 -> 0 | W20: =$G$12+SUM($G$16:G20) -> 0 | X20: =$I$12+SUM($I$16:I20)+$J$12+SUM($J$16:J20) -> 0 | Y20: =$K$12+SUM($K$16:K20) -> 0 | Z20: =$L$12+SUM($L$16:L20) -> 0 | AA20: =$F$12+SUM($F$16:F20) -> 0
M21: =SUM(G21,I21,J21,K21,L21) -> 0 | N21: =IF(F21=0,0,(F21-G21-J21-K21-I21-L21)/F21) -> 0 | O21: =IF(F21=0,0,(F21-G21/UTILIZACION-I21/UTILIZACION-J21/UTILIZACION-K21-L21)/F21) -> 0 | T21: =IF(C21<>"",IF((YEAR(C21)&MONTH(C21))<(YEAR(Inicio)&MONTH(Inicio)),YEAR(Inicio)&MONTH(Inicio),YEAR(C21)&MONTH(C21)),YEAR(C21)&MONTH(C21)) -> 19001 | U21: =AA21-Y21-X21-W21 -> 0 | W21: =$G$12+SUM($G$16:G21) -> 0 | X21: =$I$12+SUM($I$16:I21)+$J$12+SUM($J$16:J21) -> 0 | Y21: =$K$12+SUM($K$16:K21) -> 0 | Z21: =$L$12+SUM($L$16:L21) -> 0 | AA21: =$F$12+SUM($F$16:F21) -> 0
M22: =SUM(G22,I22,J22,K22,L22) -> 0 | N22: =IF(F22=0,0,(F22-G22-J22-K22-I22-L22)/F22) -> 0 | O22: =IF(F22=0,0,(F22-G22/UTILIZACION-I22/UTILIZACION-J22/UTILIZACION-K22-L22)/F22) -> 0 | T22: =IF(C22<>"",IF((YEAR(C22)&MONTH(C22))<(YEAR(Inicio)&MONTH(Inicio)),YEAR(Inicio)&MONTH(Inicio),YEAR(C22)&MONTH(C22)),YEAR(C22)&MONTH(C22)) -> 19001 | U22: =AA22-Y22-X22-W22 -> 0 | W22: =$G$12+SUM($G$16:G22) -> 0 | X22: =$I$12+SUM($I$16:I22)+$J$12+SUM($J$16:J22) -> 0 | Y22: =$K$12+SUM($K$16:K22) -> 0 | Z22: =$L$12+SUM($L$16:L22) -> 0 | AA22: =$F$12+SUM($F$16:F22) -> 0
M23: =SUM(G23,I23,J23,K23,L23) -> 0 | N23: =IF(F23=0,0,(F23-G23-J23-K23-I23-L23)/F23) -> 0 | O23: =IF(F23=0,0,(F23-G23/UTILIZACION-I23/UTILIZACION-J23/UTILIZACION-K23-L23)/F23) -> 0 | T23: =IF(C23<>"",IF((YEAR(C23)&MONTH(C23))<(YEAR(Inicio)&MONTH(Inicio)),YEAR(Inicio)&MONTH(Inicio),YEAR(C23)&MONTH(C23)),YEAR(C23)&MONTH(C23)) -> 19001 | U23: =AA23-Y23-X23-W23 -> 0 | W23: =$G$12+SUM($G$16:G23) -> 0 | X23: =$I$12+SUM($I$16:I23)+$J$12+SUM($J$16:J23) -> 0 | Y23: =$K$12+SUM($K$16:K23) -> 0 | Z23: =$L$12+SUM($L$16:L23) -> 0 | AA23: =$F$12+SUM($F$16:F23) -> 0
M24: =SUM(G24,I24,J24,K24,L24) -> 0 | N24: =IF(F24=0,0,(F24-G24-J24-K24-I24-L24)/F24) -> 0 | O24: =IF(F24=0,0,(F24-G24/UTILIZACION-I24/UTILIZACION-J24/UTILIZACION-K24-L24)/F24) -> 0 | T24: =IF(C24<>"",IF((YEAR(C24)&MONTH(C24))<(YEAR(Inicio)&MONTH(Inicio)),YEAR(Inicio)&MONTH(Inicio),YEAR(C24)&MONTH(C24)),YEAR(C24)&MONTH(C24)) -> 19001 | U24: =AA24-Y24-X24-W24 -> 0 | W24: =$G$12+SUM($G$16:G24) -> 0 | X24: =$I$12+SUM($I$16:I24)+$J$12+SUM($J$16:J24) -> 0 | Y24: =$K$12+SUM($K$16:K24) -> 0 | Z24: =$L$12+SUM($L$16:L24) -> 0 | AA24: =$F$12+SUM($F$16:F24) -> 0
M25: =SUM(G25,I25,J25,K25,L25) -> 0 | N25: =IF(F25=0,0,(F25-G25-J25-K25-I25-L25)/F25) -> 0 | O25: =IF(F25=0,0,(F25-G25/UTILIZACION-I25/UTILIZACION-J25/UTILIZACION-K25-L25)/F25) -> 0 | T25: =IF(C25<>"",IF((YEAR(C25)&MONTH(C25))<(YEAR(Inicio)&MONTH(Inicio)),YEAR(Inicio)&MONTH(Inicio),YEAR(C25)&MONTH(C25)),YEAR(C25)&MONTH(C25)) -> 19001 | U25: =AA25-Y25-X25-W25 -> 0 | W25: =$G$12+SUM($G$16:G25) -> 0 | X25: =$I$12+SUM($I$16:I25)+$J$12+SUM($J$16:J25) -> 0 | Y25: =$K$12+SUM($K$16:K25) -> 0 | Z25: =$L$12+SUM($L$16:L25) -> 0 | AA25: =$F$12+SUM($F$16:F25) -> 0
M26: =SUM(G26,I26,J26,K26,L26) -> 0 | N26: =IF(F26=0,0,(F26-G26-J26-K26-I26-L26)/F26) -> 0 | O26: =IF(F26=0,0,(F26-G26/UTILIZACION-I26/UTILIZACION-J26/UTILIZACION-K26-L26)/F26) -> 0 | T26: =IF(C26<>"",IF((YEAR(C26)&MONTH(C26))<(YEAR(Inicio)&MONTH(Inicio)),YEAR(Inicio)&MONTH(Inicio),YEAR(C26)&MONTH(C26)),YEAR(C26)&MONTH(C26)) -> 19001 | U26: =AA26-Y26-X26-W26 -> 0 | W26: =$G$12+SUM($G$16:G26) -> 0 | X26: =$I$12+SUM($I$16:I26)+$J$12+SUM($J$16:J26) -> 0 | Y26: =$K$12+SUM($K$16:K26) -> 0 | Z26: =$L$12+SUM($L$16:L26) -> 0 | AA26: =$F$12+SUM($F$16:F26) -> 0
M27: =SUM(G27,I27,J27,K27,L27) -> 0 | N27: =IF(F27=0,0,(F27-G27-J27-K27-I27-L27)/F27) -> 0 | O27: =IF(F27=0,0,(F27-G27/UTILIZACION-I27/UTILIZACION-J27/UTILIZACION-K27-L27)/F27) -> 0 | T27: =IF(C27<>"",IF((YEAR(C27)&MONTH(C27))<(YEAR(Inicio)&MONTH(Inicio)),YEAR(Inicio)&MONTH(Inicio),YEAR(C27)&MONTH(C27)),YEAR(C27)&MONTH(C27)) -> 19001 | U27: =AA27-Y27-X27-W27 -> 0 | W27: =$G$12+SUM($G$16:G27) -> 0 | X27: =$I$12+SUM($I$16:I27)+$J$12+SUM($J$16:J27) -> 0 | Y27: =$K$12+SUM($K$16:K27) -> 0 | Z27: =$L$12+SUM($L$16:L27) -> 0 | AA27: =$F$12+SUM($F$16:F27) -> 0
M28: =SUM(G28,I28,J28,K28,L28) -> 0 | N28: =IF(F28=0,0,(F28-G28-J28-K28-I28-L28)/F28) -> 0 | O28: =IF(F28=0,0,(F28-G28/UTILIZACION-I28/UTILIZACION-J28/UTILIZACION-K28-L28)/F28) -> 0 | T28: =IF(C28<>"",IF((YEAR(C28)&MONTH(C28))<(YEAR(Inicio)&MONTH(Inicio)),YEAR(Inicio)&MONTH(Inicio),YEAR(C28)&MONTH(C28)),YEAR(C28)&MONTH(C28)) -> 19001 | U28: =AA28-Y28-X28-W28 -> 0 | W28: =$G$12+SUM($G$16:G28) -> 0 | X28: =$I$12+SUM($I$16:I28)+$J$12+SUM($J$16:J28) -> 0 | Y28: =$K$12+SUM($K$16:K28) -> 0 | Z28: =$L$12+SUM($L$16:L28) -> 0 | AA28: =$F$12+SUM($F$16:F28) -> 0
... M35: =SUM(G35,I35,J35,K35,L35) -> 0 | N35: =IF(F35=0,0,(F35-G35-J35-K35-I35-L35)/F35) -> 0 | O35: =IF(F35=0,0,(F35-G35/UTILIZACION-I35/UTILIZACION-J35/UTILIZACION-K35-L35)/F35) -> 0 | T35: =IF(C35<>"",IF((YEAR(C35)&MONTH(C35))<(YEAR(Inicio)&MONTH(Inicio)),YEAR(Inicio)&MONTH(Inicio),YEAR(C35)&MONTH(C35)),YEAR(C35)&MONTH(C35)) -> 19001 | U35: =AA35-Y35-X35-W35 -> 0 | W35: =$G$12+SUM($G$16:G35) -> 0 | X35: =$I$12+SUM($I$16:I35)+$J$12+SUM($J$16:J35) -> 0 | Y35: =$K$12+SUM($K$16:K35) -> 0 | Z35: =$L$12+SUM($L$16:L35) -> 0 | AA35: =$F$12+SUM($F$16:F35) -> 0
B36: TOTAL AMPLIACIONES | F36: =SUMIF(B16:B35,"AMPLIACION",F16:F35) -> 0 | G36: =SUMIF(B16:B35,"AMPLIACION",G16:G35) -> 0 | H36: =SUMIF(B16:B35,"AMPLIACION",H16:H35) -> 0 | I36: =SUMIF(B16:B35,"AMPLIACION",I16:I35) -> 0 | J36: =SUMIF(B16:B35,"AMPLIACION",J16:J35) -> 0 | K36: =SUMIF(B16:B35,"AMPLIACION",K16:K35) -> 0 | L36: =SUMIF(B16:B35,"AMPLIACION",L16:L35) -> 0 | M36: =SUM(G36,I36,J36,K36,L36) -> 0 | N36: =IF(F36=0,0,(F36-G36-J36-K36-I36-L36)/F36) -> 0 | O36: =IF(F36=0,0,(F36-G36/0.93-I36/0.93-J36/0.93-K36-L36)/F36) -> 0
B37: TOTAL REESTIMACIONES | F37: =SUMIF(B16:B35,"REESTIMACION",F16:F35) -> 0 | G37: =SUMIF(B16:B35,"REESTIMACION",G16:G35) -> 0 | H37: =SUMIF(B16:B35,"REESTIMACION",H16:H35) -> 0 | I37: =SUMIF(B16:B35,"REESTIMACION",I16:I35) -> 0 | J37: =SUMIF(B16:B35,"REESTIMACION",J16:J35) -> 0 | K37: =SUMIF(B16:B35,"REESTIMACION",K16:K35) -> 0 | L37: =SUMIF(B16:B35,"REESTIMACION",L16:L35) -> 0 | M37: =SUM(G37,I37,J37,K37,L37) -> 0 | N37: =IF(F37=0,0,(F37-G37-J37-K37-I37-L37)/F37) -> 0 | O37: =IF(F37=0,0,(F37-G37/0.93-I37/0.93-J37/0.93-K37-L37)/F37) -> 0
B48: Comentarios adicionales Cost Overview
B49: <dd/mm/aaaa> comentario <dd/mm/aaaa> comentario <dd/mm/aaaa> comentario

Sheet Resources
B2: WBS-Element | C2: ='Project Infor'!C10 -> ZEZ-AT00001-1001 | D2: ='Project Infor'!C11 -> Asistencia técnica para desarrollo Java/.Net/…
B5: Equipo GETRONICS. Costes hora por perfil. | E5: (!) IMPORTANTE: se debe indicar si cada perfil es o no INTERCO
B6: COD EMPLEADO | C6: INICIALES | D6: INTERCO | E6: ROL | G6: ='Project Infor'!C8 -> 44287 | H6: =EOMONTH(G6,1) -> 44347 | I6: =EOMONTH(H6,1) -> 44377 | J6: =EOMONTH(I6,1) -> 44408 | K6: =EOMONTH(J6,1) -> 44439 | L6: =EOMONTH(K6,1) -> 44469 | M6: =EOMONTH(L6,1) -> 44500 | N6: =EOMONTH(M6,1) -> 44530 | O6: =EOMONTH(N6,1) -> 44561 | ... AE6: =EOMONTH(AD6,1) -> 45046
F7: Coste/hora
B8: =B7 -> 0 | C8: =C7 -> 0 | D8: =D7 -> 0 | E8: =E7 -> 0 | F8: Tarifa venta (Hora o Jornada)
F9: Coste/hora
B10: =B9 -> 0 | C10: =C9 -> 0 | D10: =D9 -> 0 | E10: =E9 -> 0 | F10: Tarifa venta (Hora o Jornada)
F11: Coste/hora
B12: =B11 -> 0 | C12: =C11 -> 0 | D12: =D11 -> 0 | E12: =E11 -> 0 | F12: Tarifa venta (Hora o Jornada)
F13: Coste/hora
B14: =B13 -> 0 | C14: =C13 -> 0 | D14: =D13 -> 0 | E14: =E13 -> 0 | F14: Tarifa venta (Hora o Jornada)
F15: Coste/hora
B16: =B15 -> 0 | C16: =C15 -> 0 | D16: =D15 -> 0 | E16: =E15 -> 0 | F16: Tarifa venta (Hora o Jornada)
F17: Coste/hora
B18: =B17 -> 0 | C18: =C17 -> 0 | D18: =D17 -> 0 | E18: =E17 -> 0 | F18: Tarifa venta (Hora o Jornada)
F19: Coste/hora
B20: =B19 -> 0 | C20: =C19 -> 0 | D20: =D19 -> 0 | E20: =E19 -> 0 | F20: Tarifa venta (Hora o Jornada)
F21: Coste/hora
B22: =B21 -> 0 | C22: =C21 -> 0 | D22: =D21 -> 0 | E22: =E21 -> 0 | F22: Tarifa venta (Hora o Jornada)
F23: Coste/hora
B24: =B23 -> 0 | C24: =C23 -> 0 | D24: =D23 -> 0 | E24: =E23 -> 0 | F24: Tarifa venta (Hora o Jornada)
F25: Coste/hora
B26: =B25 -> 0 | C26: =C25 -> 0 | D26: =D25 -> 0 | E26: =E25 -> 0 | F26: Tarifa venta (Hora o Jornada)
F27: Coste/hora
B28: =B27 -> 0 | C28: =C27 -> 0 | D28: =D27 -> 0 | E28: =E27 -> 0 | F28: Tarifa venta (Hora o Jornada)
F29: Coste/hora
B30: =B29 -> 0 | C30: =C29 -> 0 | D30: =D29 -> 0 | E30: =E29 -> 0 | F30: Tarifa venta (Hora o Jornada)
F31: Coste/hora
B32: =B31 -> 0 | C32: =C31 -> 0 | D32: =D31 -> 0 | E32: =E31 -> 0 | F32: Tarifa venta (Hora o Jornada)
F33: Coste/hora
B34: =B33 -> 0 | C34: =C33 -> 0 | D34: =D33 -> 0 | E34: =E33 -> 0 | F34: Tarifa venta (Hora o Jornada)
F35: Coste/hora
B36: =B35 -> 0 | C36: =C35 -> 0 | D36: =D35 -> 0 | E36: =E35 -> 0 | F36: Tarifa venta (Hora o Jornada)
B45: Tipo de Roles
B46: COD | C46: DESCRIPCION
B47: PM | C47: Project Manager
B48: CO | C48: Consultor
B49: ANF | C49: Analista Funcional
B50: AP | C50: Analista Programador
B51: PR | C51: Programador
...

Sheet Cost Planning
B2: WBS-Element | C2: ='Project Infor'!C10 -> ZEZ-AT00001-1001 | D2: ='Project Infor'!C11 -> Asistencia técnica para desarrollo Java/.Net/…
B5: Equipo GETRONICS | D5: COSTE TOTAL RECURSOS BASELINE | F5: =costerecursosbaselineactual -> 0 | H5: PENDIENTE DE PLANIFICAR | J5: =F5-SUM(F40:AF41) -> 0 | L5: PENDIENTE DE PEDIDO | N5: =-(pedidobaselineactual-SUM(H44:AF44)-SUM(H62:AF62)-SUM(H78:AF78)) -> 0
H7: =IF(H8>EOMONTH(FIN,0),"Fin",IF(H8>FECHA,"Prev","Real")) -> Real | I7: =IF(I8>EOMONTH(FIN,0),"Fin",IF(I8>FECHA,"Prev","Real")) -> Real | J7: =IF(J8>EOMONTH(FIN,0),"Fin",IF(J8>FECHA,"Prev","Real")) -> Prev | K7: =IF(K8>EOMONTH(FIN,0),"Fin",IF(K8>FECHA,"Prev","Real")) -> Prev | L7: =IF(L8>EOMONTH(FIN,0),"Fin",IF(L8>FECHA,"Prev","Real")) -> Prev | M7: =IF(M8>EOMONTH(FIN,0),"Fin",IF(M8>FECHA,"Prev","Real")) -> Prev | N7: =IF(N8>EOMONTH(FIN,0),"Fin",IF(N8>FECHA,"Prev","Real")) -> Prev | O7: =IF(O8>EOMONTH(FIN,0),"Fin",IF(O8>FECHA,"Prev","Real")) -> Prev | ... AF7: =IF(AF8>EOMONTH(FIN,0),"Fin",IF(AF8>FECHA,"Prev","Real")) -> Fin
B8: COD EMPLEADO | C8: INICIALES | D8: INTERCO | E8: ROL | F8: CODIGO INTERCO | H8: ='Project Infor'!C8 -> 44287 | I8: =EOMONTH(H8,1) -> 44347 | J8: =EOMONTH(I8,1) -> 44377 | K8: =EOMONTH(J8,1) -> 44408 | L8: =EOMONTH(K8,1) -> 44439 | M8: =EOMONTH(L8,1) -> 44469 | N8: =EOMONTH(M8,1) -> 44500 | O8: =EOMONTH(N8,1) -> 44530 | P8: =EOMONTH(O8,1) -> 44561 | ... AF8: =EOMONTH(AE8,1) -> 45046
B9: HORAS REALES RECURSOS entidad PROYECTO + INTERCO | F9: ='Project Infor'!C46 -> 0 | H9: =SUMIF($G$10:$G$39,"Horas Reales",H$10:H$39) -> 0 | I9: =SUMIF($G$10:$G$39,"Horas Reales",I$10:I$39) -> 0 | J9: =SUMIF($G$10:$G$39,"Horas Reales",J$10:J$39) -> 0 | K9: =SUMIF($G$10:$G$39,"Horas Reales",K$10:K$39) -> 0 | L9: =SUMIF($G$10:$G$39,"Horas Reales",L$10:L$39) -> 0 | M9: =SUMIF($G$10:$G$39,"Horas Reales",M$10:M$39) -> 0 | N9: =SUMIF($G$10:$G$39,"Horas Reales",N$10:N$39) -> 0 | O9: =SUMIF($G$10:$G$39,"Horas Reales",O$10:O$39) -> 0 | ... AF9: =SUMIF($G$10:$G$39,"Horas Reales",AF$10:AF$39) -> 0
B10: =IF(Resources!B7="","",Resources!B7) | C10: =IF(Resources!C7="","",Resources!C7) | D10: =IF(Resources!D7="","",Resources!D7) | E10: =IF(Resources!E7="","",Resources!E7) | G10: Horas Reales
B11: =B10 | C11: =C10 | D11: =D10 | E11: =E10 | G11: Horas/Jornadas Facturables
B12: =IF(Resources!B9="","",Resources!B9) | C12: =IF(Resources!C9="","",Resources!C9) | D12: =IF(Resources!D9="","",Resources!D9) | E12: =IF(Resources!E9="","",Resources!E9) | G12: Horas Reales
B13: =B12 | C13: =C12 | D13: =D12 | E13: =E12 | G13: Horas/Jornadas Facturables
B14: =IF(Resources!B11="","",Resources!B11) | C14: =IF(Resources!C11="","",Resources!C11) | D14: =IF(Resources!D11="","",Resources!D11) | E14: =IF(Resources!E11="","",Resources!E11) | G14: Horas Reales
B15: =B14 | C15: =C14 | D15: =D14 | E15: =E14 | G15: Horas/Jornadas Facturables
B16: =IF(Resources!B13="","",Resources!B13) | C16: =IF(Resources!C13="","",Resources!C13) | D16: =IF(Resources!D13="","",Resources!D13) | E16: =IF(Resources!E13="","",Resources!E13) | G16: Horas Reales
B17: =B16 | C17: =C16 | D17: =D16 | E17: =E16 | G17: Horas/Jornadas Facturables
B18: =IF(Resources!B15="","",Resources!B15) | C18: =IF(Resources!C15="","",Resources!C15) | D18: =IF(Resources!D15="","",Resources!D15) | E18: =IF(Resources!E15="","",Resources!E15) | G18: Horas Reales
B19: =B18 | C19: =C18 | D19: =D18 | E19: =E18 | G19: Horas/Jornadas Facturables
B20: =IF(Resources!B17="","",Resources!B17) | C20: =IF(Resources!C17="","",Resources!C17) | D20: =IF(Resources!D17="","",Resources!D17) | E20: =IF(Resources!E17="","",Resources!E17) | G20: Horas Reales
B21: =B20 | C21: =C20 | D21: =D20 | E21: =E20 | G21: Horas/Jornadas Facturables
B22: =IF(Resources!B19="","",Resources!B19) | C22: =IF(Resources!C19="","",Resources!C19) | D22: =IF(Resources!D19="","",Resources!D19) | E22: =IF(Resources!E19="","",Resources!E19) | G22: Horas Reales
B23: =B22 | C23: =C22 | D23: =D22 | E23: =E22 | G23: Horas/Jornadas Facturables
B24: =IF(Resources!B21="","",Resources!B21) | C24: =IF(Resources!C21="","",Resources!C21) | D24: =IF(Resources!D21="","",Resources!D21) | E24: =IF(Resources!E21="","",Resources!E21) | G24: Horas Reales
B25: =B24 | C25: =C24 | D25: =D24 | E25: =E24 | G25: Horas/Jornadas Facturables
B26: =IF(Resources!B23="","",Resources!B23) | C26: =IF(Resources!C23="","",Resources!C23) | D26: =IF(Resources!D23="","",Resources!D23) | E26: =IF(Resources!E23="","",Resources!E23) | G26: Horas Reales
B27: =B26 | C27: =C26 | D27: =D26 | E27: =E26 | G27: Horas/Jornadas Facturables
B28: =IF(Resources!B25="","",Resources!B25) | C28: =IF(Resources!C25="","",Resources!C25) | D28: =IF(Resources!D25="","",Resources!D25) | E28: =IF(Resources!E25="","",Resources!E25) | G28: Horas Reales
B29: =B28 | C29: =C28 | D29: =D28 | E29: =E28 | G29: Horas/Jornadas Facturables
B30: =IF(Resources!B27="","",Resources!B27) | C30: =IF(Resources!C27="","",Resources!C27) | D30: =IF(Resources!D27="","",Resources!D27) | E30: =IF(Resources!E27="","",Resources!E27) | G30: Horas Reales
B31: =B30 | C31: =C30 | D31: =D30 | E31: =E30 | G31: Horas/Jornadas Facturables
B32: =IF(Resources!B29="","",Resources!B29) | C32: =IF(Resources!C29="","",Resources!C29) | D32: =IF(Resources!D29="","",Resources!D29) | E32: =IF(Resources!E29="","",Resources!E29) | G32: Horas Reales
B33: =B32 | C33: =C32 | D33: =D32 | E33: =E32 | G33: Horas/Jornadas Facturables
B34: =IF(Resources!B31="","",Resources!B31) | C34: =IF(Resources!C31="","",Resources!C31) | D34: =IF(Resources!D31="","",Resources!D31) | E34: =IF(Resources!E31="","",Resources!E31) | G34: Horas Reales
B35: =B34 | C35: =C34 | D35: =D34 | E35: =E34 | G35: Horas/Jornadas Facturables
B36: =IF(Resources!B33="","",Resources!B33) | C36: =IF(Resources!C33="","",Resources!C33) | D36: =IF(Resources!D33="","",Resources!D33) | E36: =IF(Resources!E33="","",Resources!E33) | G36: Horas Reales
B37: =B36 | C37: =C36 | D37: =D36 | E37: =E36 | G37: Horas/Jornadas Facturables
B38: =IF(Resources!B35="","",Resources!B35) | C38: =IF(Resources!C35="","",Resources!C35) | D38: =IF(Resources!D35="","",Resources!D35) | E38: =IF(Resources!E35="","",Resources!E35) | G38: Horas Reales
B39: =B38 | C39: =C38 | D39: =D38 | E39: =E38 | G39: Horas/Jornadas Facturables
B40: COSTE TOTAL RECURSOS entidad PROYECTO (euros) | F40: ='Project Infor'!C47 -> 0 | H40: {=SUMPRODUCT(($D$10:$D$39="NO")*1,($G$10:$G$39="Horas Reales")*1,H$10:H$39,Resources!G7:G36)+H42} -> 0 | I40: {=SUMPRODUCT(($D$10:$D$39="NO")*1,($G$10:$G$39="Horas Reales")*1,I$10:I$39,Resources!H7:H36)+I42} -> 0 | J40: {=SUMPRODUCT(($D$10:$D$39="NO")*1,($G$10:$G$39="Horas Reales")*1,J$10:J$39,Resources!I7:I36)+J42} -> 0 | K40: {=SUMPRODUCT(($D$10:$D$39="NO")*1,($G$10:$G$39="Horas Reales")*1,K$10:K$39,Resources!J7:J36)+K42} -> 0 | L40: {=SUMPRODUCT(($D$10:$D$39="NO")*1,($G$10:$G$39="Horas Reales")*1,L$10:L$39,Resources!K7:K36)+L42} -> 0 | M40: {=SUMPRODUCT(($D$10:$D$39="NO")*1,($G$10:$G$39="Horas Reales")*1,M$10:M$39,Resources!L7:L36)+M42} -> 0 | N40: {=SUMPRODUCT(($D$10:$D$39="NO")*1,($G$10:$G$39="Horas Reales")*1,N$10:N$39,Resources!M7:M36)+N42} -> 0 | O40: {=SUMPRODUCT(($D$10:$D$39="NO")*1,($G$10:$G$39="Horas Reales")*1,O$10:O$39,Resources!N7:N36)+O42} -> 0 | ... AF40: {=SUMPRODUCT(($D$10:$D$39="NO")*1,($G$10:$G$39="Horas Reales")*1,AF$10:AF$39,Resources!AE7:AE36)+AF42} -> 0
B41: COSTE TOTAL RECURSOS INTERCO (euros) | H41: {=SUMPRODUCT(($D$10:$D$39="INTERCO")*1,($G$10:$G$39="Horas Reales")*1,H$10:H$39,Resources!G7:G36)+H43} -> 0 | I41: {=SUMPRODUCT(($D$10:$D$39="INTERCO")*1,($G$10:$G$39="Horas Reales")*1,I$10:I$39,Resources!H7:H36)+I43} -> 0 | J41: {=SUMPRODUCT(($D$10:$D$39="INTERCO")*1,($G$10:$G$39="Horas Reales")*1,J$10:J$39,Resources!I7:I36)+J43} -> 0 | K41: {=SUMPRODUCT(($D$10:$D$39="INTERCO")*1,($G$10:$G$39="Horas Reales")*1,K$10:K$39,Resources!J7:J36)+K43} -> 0 | L41: {=SUMPRODUCT(($D$10:$D$39="INTERCO")*1,($G$10:$G$39="Horas Reales")*1,L$10:L$39,Resources!K7:K36)+L43} -> 0 | M41: {=SUMPRODUCT(($D$10:$D$39="INTERCO")*1,($G$10:$G$39="Horas Reales")*1,M$10:M$39,Resources!L7:L36)+M43} -> 0 | N41: {=SUMPRODUCT(($D$10:$D$39="INTERCO")*1,($G$10:$G$39="Horas Reales")*1,N$10:N$39,Resources!M7:M36)+N43} -> 0 | O41: {=SUMPRODUCT(($D$10:$D$39="INTERCO")*1,($G$10:$G$39="Horas Reales")*1,O$10:O$39,Resources!N7:N36)+O43} -> 0 | ... AF41: {=SUMPRODUCT(($D$10:$D$39="INTERCO")*1,($G$10:$G$39="Horas Reales")*1,AF$10:AF$39,Resources!AE7:AE36)+AF43} -> 0
C42: AJUSTE con SAP (en EUROS) para perfiles NO INTERCO
C43: AJUSTE con SAP (en EUROS) para perfiles INTERCO
B44: VENTA TOTAL HORAS/JORNADAS FACTURABLES (euros) | H44: {=SUMPRODUCT(($G$10:$G$39="Horas/Jornadas Facturables")*1,H$10:H$39,Resources!G7:G36)} -> 0 | I44: {=SUMPRODUCT(($G$10:$G$39="Horas/Jornadas Facturables")*1,I$10:I$39,Resources!H7:H36)} -> 0 | J44: {=SUMPRODUCT(($G$10:$G$39="Horas/Jornadas Facturables")*1,J$10:J$39,Resources!I7:I36)} -> 0 | K44: {=SUMPRODUCT(($G$10:$G$39="Horas/Jornadas Facturables")*1,K$10:K$39,Resources!J7:J36)} -> 0 | L44: {=SUMPRODUCT(($G$10:$G$39="Horas/Jornadas Facturables")*1,L$10:L$39,Resources!K7:K36)} -> 0 | M44: {=SUMPRODUCT(($G$10:$G$39="Horas/Jornadas Facturables")*1,M$10:M$39,Resources!L7:L36)} -> 0 | N44: {=SUMPRODUCT(($G$10:$G$39="Horas/Jornadas Facturables")*1,N$10:N$39,Resources!M7:M36)} -> 0 | O44: {=SUMPRODUCT(($G$10:$G$39="Horas/Jornadas Facturables")*1,O$10:O$39,Resources!N7:N36)} -> 0 | ... AF44: {=SUMPRODUCT(($G$10:$G$39="Horas/Jornadas Facturables")*1,AF$10:AF$39,Resources!AE7:AE36)} -> 0
...

Sheet Monthly View
B2: WBS-Element | C2: ='Project Infor'!C10 -> ZEZ-AT00001-1001 | D2: ='Project Infor'!C11 -> Asistencia técnica para desarrollo Java/.Net/… | I2: (!) La VENTA total planificada excede el PEDIDO | M2: ='Cost Planning'!N5 -> 0
E4: =IF(E5>EOMONTH(FIN,0),"Fin",IF(E5>FECHA,"Prev","Real")) -> Real | F4: =IF(F5>EOMONTH(FIN,0),"Fin",IF(F5>FECHA,"Prev","Real")) -> Real | G4: =IF(G5>EOMONTH(FIN,0),"Fin",IF(G5>FECHA,"Prev","Real")) -> Prev | H4: =IF(H5>EOMONTH(FIN,0),"Fin",IF(H5>FECHA,"Prev","Real")) -> Prev | I4: =IF(I5>EOMONTH(FIN,0),"Fin",IF(I5>FECHA,"Prev","Real")) -> Prev | J4: =IF(J5>EOMONTH(FIN,0),"Fin",IF(J5>FECHA,"Prev","Real")) -> Prev | K4: =IF(K5>EOMONTH(FIN,0),"Fin",IF(K5>FECHA,"Prev","Real")) -> Prev | L4: =IF(L5>EOMONTH(FIN,0),"Fin",IF(L5>FECHA,"Prev","Real")) -> Prev | ... AC4: =IF(AC5>EOMONTH(FIN,0),"Fin",IF(AC5>FECHA,"Prev","Real")) -> Fin
B5: LINEA BASE ACTUAL | D5: INICIAL | E5: ='Project Infor'!C8 -> 44287 | F5: =EOMONTH(E5,1) -> 44347 | G5: =EOMONTH(F5,1) -> 44377 | H5: =EOMONTH(G5,1) -> 44408 | I5: =EOMONTH(H5,1) -> 44439 | J5: =EOMONTH(I5,1) -> 44469 | K5: =EOMONTH(J5,1) -> 44500 | L5: =EOMONTH(K5,1) -> 44530 | M5: =EOMONTH(L5,1) -> 44561 | ... AC5: =EOMONTH(AB5,1) -> 45046
B6: + INGRESOS PREVISTOS | D6: ='Project Infor'!C28 -> 0 | E6: =D6+SUMIF('Cost Overview'!$T$16:$T$35,(YEAR(E$5)&MONTH(E$5)),'Cost Overview'!$F$16:$F$35) -> 0 | F6: =E6+SUMIF('Cost Overview'!$T$16:$T$35,(YEAR(F$5)&MONTH(F$5)),'Cost Overview'!$F$16:$F$35) -> 0 | G6: =F6+SUMIF('Cost Overview'!$T$16:$T$35,(YEAR(G$5)&MONTH(G$5)),'Cost Overview'!$F$16:$F$35) -> 0 | H6: =G6+SUMIF('Cost Overview'!$T$16:$T$35,(YEAR(H$5)&MONTH(H$5)),'Cost Overview'!$F$16:$F$35) -> 0 | I6: =H6+SUMIF('Cost Overview'!$T$16:$T$35,(YEAR(I$5)&MONTH(I$5)),'Cost Overview'!$F$16:$F$35) -> 0 | J6: =I6+SUMIF('Cost Overview'!$T$16:$T$35,(YEAR(J$5)&MONTH(J$5)),'Cost Overview'!$F$16:$F$35) -> 0 | K6: =J6+SUMIF('Cost Overview'!$T$16:$T$35,(YEAR(K$5)&MONTH(K$5)),'Cost Overview'!$F$16:$F$35) -> 0 | L6: =K6+SUMIF('Cost Overview'!$T$16:$T$35,(YEAR(L$5)&MONTH(L$5)),'Cost Overview'!$F$16:$F$35) -> 0 | ... AC6: =AB6+SUMIF('Cost Overview'!$T$16:$T$35,(YEAR(AC$5)&MONTH(AC$5)),'Cost Overview'!$F$16:$F$35) -> 0
B7: HORAS | D7: ='Project Infor'!C29 -> 0 | E7: =D7+SUMIF('Cost Overview'!$T$16:$T$35,(YEAR(E$5)&MONTH(E$5)),'Cost Overview'!$H$16:$H$35) -> 0 | F7: =E7+SUMIF('Cost Overview'!$T$16:$T$35,(YEAR(F$5)&MONTH(F$5)),'Cost Overview'!$H$16:$H$35) -> 0 | G7: =F7+SUMIF('Cost Overview'!$T$16:$T$35,(YEAR(G$5)&MONTH(G$5)),'Cost Overview'!$H$16:$H$35) -> 0 | H7: =G7+SUMIF('Cost Overview'!$T$16:$T$35,(YEAR(H$5)&MONTH(H$5)),'Cost Overview'!$H$16:$H$35) -> 0 | I7: =H7+SUMIF('Cost Overview'!$T$16:$T$35,(YEAR(I$5)&MONTH(I$5)),'Cost Overview'!$H$16:$H$35) -> 0 | J7: =I7+SUMIF('Cost Overview'!$T$16:$T$35,(YEAR(J$5)&MONTH(J$5)),'Cost Overview'!$H$16:$H$35) -> 0 | K7: =J7+SUMIF('Cost Overview'!$T$16:$T$35,(YEAR(K$5)&MONTH(K$5)),'Cost Overview'!$H$16:$H$35) -> 0 | L7: =K7+SUMIF('Cost Overview'!$T$16:$T$35,(YEAR(L$5)&MONTH(L$5)),'Cost Overview'!$H$16:$H$35) -> 0 | ... AC7: =AB7+SUMIF('Cost Overview'!$T$16:$T$35,(YEAR(AC$5)&MONTH(AC$5)),'Cost Overview'!$H$16:$H$35) -> 0
B8: - COSTE RECURSOS | D8: ='Project Infor'!C30 -> 0 | E8: =D8+SUMIF('Cost Overview'!$T$16:$T$35,(YEAR(E$5)&MONTH(E$5)),'Cost Overview'!$G$16:$G$35) -> 0 | F8: =E8+SUMIF('Cost Overview'!$T$16:$T$35,(YEAR(F$5)&MONTH(F$5)),'Cost Overview'!$G$16:$G$35) -> 0 | G8: =F8+SUMIF('Cost Overview'!$T$16:$T$35,(YEAR(G$5)&MONTH(G$5)),'Cost Overview'!$G$16:$G$35) -> 0 | H8: =G8+SUMIF('Cost Overview'!$T$16:$T$35,(YEAR(H$5)&MONTH(H$5)),'Cost Overview'!$G$16:$G$35) -> 0 | I8: =H8+SUMIF('Cost Overview'!$T$16:$T$35,(YEAR(I$5)&MONTH(I$5)),'Cost Overview'!$G$16:$G$35) -> 0 | J8: =I8+SUMIF('Cost Overview'!$T$16:$T$35,(YEAR(J$5)&MONTH(J$5)),'Cost Overview'!$G$16:$G$35) -> 0 | K8: =J8+SUMIF('Cost Overview'!$T$16:$T$35,(YEAR(K$5)&MONTH(K$5)),'Cost Overview'!$G$16:$G$35) -> 0 | L8: =K8+SUMIF('Cost Overview'!$T$16:$T$35,(YEAR(L$5)&MONTH(L$5)),'Cost Overview'!$G$16:$G$35) -> 0 | ... AC8: =AB8+SUMIF('Cost Overview'!$T$16:$T$35,(YEAR(AC$5)&MONTH(AC$5)),'Cost Overview'!$G$16:$G$35) -> 0
B9: - RIESGOS | D9: ='Project Infor'!C31 -> 0 | E9: =D9+SUMIF('Cost Overview'!$T$16:$T$35,(YEAR(E$5)&MONTH(E$5)),'Cost Overview'!$I$16:$I$35) -> 0 | F9: =E9+SUMIF('Cost Overview'!$T$16:$T$35,(YEAR(F$5)&MONTH(F$5)),'Cost Overview'!$I$16:$I$35) -> 0 | G9: =F9+SUMIF('Cost Overview'!$T$16:$T$35,(YEAR(G$5)&MONTH(G$5)),'Cost Overview'!$I$16:$I$35) -> 0 | H9: =G9+SUMIF('Cost Overview'!$T$16:$T$35,(YEAR(H$5)&MONTH(H$5)),'Cost Overview'!$I$16:$I$35) -> 0 | I9: =H9+SUMIF('Cost Overview'!$T$16:$T$35,(YEAR(I$5)&MONTH(I$5)),'Cost Overview'!$I$16:$I$35) -> 0 | J9: =I9+SUMIF('Cost Overview'!$T$16:$T$35,(YEAR(J$5)&MONTH(J$5)),'Cost Overview'!$I$16:$I$35) -> 0 | K9: =J9+SUMIF('Cost Overview'!$T$16:$T$35,(YEAR(K$5)&MONTH(K$5)),'Cost Overview'!$I$16:$I$35) -> 0 | L9: =K9+SUMIF('Cost Overview'!$T$16:$T$35,(YEAR(L$5)&MONTH(L$5)),'Cost Overview'!$I$16:$I$35) -> 0 | ... AC9: =AB9+SUMIF('Cost Overview'!$T$16:$T$35,(YEAR(AC$5)&MONTH(AC$5)),'Cost Overview'!$I$16:$I$35) -> 0
B10: - GARANTIA | D10: ='Project Infor'!C32 -> 0 | E10: =D10+SUMIF('Cost Overview'!$T$16:$T$35,(YEAR(E$5)&MONTH(E$5)),'Cost Overview'!$J$16:$J$35) -> 0 | F10: =E10+SUMIF('Cost Overview'!$T$16:$T$35,(YEAR(F$5)&MONTH(F$5)),'Cost Overview'!$J$16:$J$35) -> 0 | G10: =F10+SUMIF('Cost Overview'!$T$16:$T$35,(YEAR(G$5)&MONTH(G$5)),'Cost Overview'!$J$16:$J$35) -> 0 | H10: =G10+SUMIF('Cost Overview'!$T$16:$T$35,(YEAR(H$5)&MONTH(H$5)),'Cost Overview'!$J$16:$J$35) -> 0 | I10: =H10+SUMIF('Cost Overview'!$T$16:$T$35,(YEAR(I$5)&MONTH(I$5)),'Cost Overview'!$J$16:$J$35) -> 0 | J10: =I10+SUMIF('Cost Overview'!$T$16:$T$35,(YEAR(J$5)&MONTH(J$5)),'Cost Overview'!$J$16:$J$35) -> 0 | K10: =J10+SUMIF('Cost Overview'!$T$16:$T$35,(YEAR(K$5)&MONTH(K$5)),'Cost Overview'!$J$16:$J$35) -> 0 | L10: =K10+SUMIF('Cost Overview'!$T$16:$T$35,(YEAR(L$5)&MONTH(L$5)),'Cost Overview'!$J$16:$J$35) -> 0 | ... AC10: =AB10+SUMIF('Cost Overview'!$T$16:$T$35,(YEAR(AC$5)&MONTH(AC$5)),'Cost Overview'!$J$16:$J$35) -> 0
B11: - GASTOS | D11: ='Project Infor'!C33 -> 0 | E11: =D11+SUMIF('Cost Overview'!$T$16:$T$35,(YEAR(E$5)&MONTH(E$5)),'Cost Overview'!$K$16:$K$35) -> 0 | F11: =E11+SUMIF('Cost Overview'!$T$16:$T$35,(YEAR(F$5)&MONTH(F$5)),'Cost Overview'!$K$16:$K$35) -> 0 | G11: =F11+SUMIF('Cost Overview'!$T$16:$T$35,(YEAR(G$5)&MONTH(G$5)),'Cost Overview'!$K$16:$K$35) -> 0 | H11: =G11+SUMIF('Cost Overview'!$T$16:$T$35,(YEAR(H$5)&MONTH(H$5)),'Cost Overview'!$K$16:$K$35) -> 0 | I11: =H11+SUMIF('Cost Overview'!$T$16:$T$35,(YEAR(I$5)&MONTH(I$5)),'Cost Overview'!$K$16:$K$35) -> 0 | J11: =I11+SUMIF('Cost Overview'!$T$16:$T$35,(YEAR(J$5)&MONTH(J$5)),'Cost Overview'!$K$16:$K$35) -> 0 | K11: =J11+SUMIF('Cost Overview'!$T$16:$T$35,(YEAR(K$5)&MONTH(K$5)),'Cost Overview'!$K$16:$K$35) -> 0 | L11: =K11+SUMIF('Cost Overview'!$T$16:$T$35,(YEAR(L$5)&MONTH(L$5)),'Cost Overview'!$K$16:$K$35) -> 0 | ... AC11: =AB11+SUMIF('Cost Overview'!$T$16:$T$35,(YEAR(AC$5)&MONTH(AC$5)),'Cost Overview'!$K$16:$K$35) -> 0
B12: - COMPRAS | D12: ='Project Infor'!C34 -> 0 | E12: =D12+SUMIF('Cost Overview'!$T$16:$T$35,(YEAR(E$5)&MONTH(E$5)),'Cost Overview'!$L$16:$L$35) -> 0 | F12: =E12+SUMIF('Cost Overview'!$T$16:$T$35,(YEAR(F$5)&MONTH(F$5)),'Cost Overview'!$L$16:$L$35) -> 0 | G12: =F12+SUMIF('Cost Overview'!$T$16:$T$35,(YEAR(G$5)&MONTH(G$5)),'Cost Overview'!$L$16:$L$35) -> 0 | H12: =G12+SUMIF('Cost Overview'!$T$16:$T$35,(YEAR(H$5)&MONTH(H$5)),'Cost Overview'!$L$16:$L$35) -> 0 | I12: =H12+SUMIF('Cost Overview'!$T$16:$T$35,(YEAR(I$5)&MONTH(I$5)),'Cost Overview'!$L$16:$L$35) -> 0 | J12: =I12+SUMIF('Cost Overview'!$T$16:$T$35,(YEAR(J$5)&MONTH(J$5)),'Cost Overview'!$L$16:$L$35) -> 0 | K12: =J12+SUMIF('Cost Overview'!$T$16:$T$35,(YEAR(K$5)&MONTH(K$5)),'Cost Overview'!$L$16:$L$35) -> 0 | L12: =K12+SUMIF('Cost Overview'!$T$16:$T$35,(YEAR(L$5)&MONTH(L$5)),'Cost Overview'!$L$16:$L$35) -> 0 | ... AC12: =AB12+SUMIF('Cost Overview'!$T$16:$T$35,(YEAR(AC$5)&MONTH(AC$5)),'Cost Overview'!$L$16:$L$35) -> 0
B13: COSTE DIRECTO | D13: =SUM(D8:D12) -> 0 | E13: =SUM(E8:E12) -> 0 | F13: =SUM(F8:F12) -> 0 | G13: =SUM(G8:G12) -> 0 | H13: =SUM(H8:H12) -> 0 | I13: =SUM(I8:I12) -> 0 | J13: =SUM(J8:J12) -> 0 | K13: =SUM(K8:K12) -> 0 | ... AC13: =SUM(AC8:AC12) -> 0
B14: MARGEN DIRECTO (euros) | D14: =D6-D13 -> 0 | E14: =E6-E13 -> 0 | F14: =F6-F13 -> 0 | G14: =G6-G13 -> 0 | H14: =H6-H13 -> 0 | I14: =I6-I13 -> 0 | J14: =J6-J13 -> 0 | K14: =K6-K13 -> 0 | ... AC14: =AC6-AC13 -> 0
B15: MARGEN DIRECTO (%) | D15: =IF(D6=0,0,(D6-D13)/D6) -> 0 | E15: =IF(E6=0,0,(E6-E13)/E6) -> 0 | F15: =IF(F6=0,0,(F6-F13)/F6) -> 0 | G15: =IF(G6=0,0,(G6-G13)/G6) -> 0 | H15: =IF(H6=0,0,(H6-H13)/H6) -> 0 | I15: =IF(I6=0,0,(I6-I13)/I6) -> 0 | J15: =IF(J6=0,0,(J6-J13)/J6) -> 0 | K15: =IF(K6=0,0,(K6-K13)/K6) -> 0 | ... AC15: =IF(AC6=0,0,(AC6-AC13)/AC6) -> 0
B17: REALIZADO + PREVISTO MES | E17: ='Project Infor'!C8 -> 44287 | F17: =EOMONTH(E17,1) -> 44347 | G17: =EOMONTH(F17,1) -> 44377 | H17: =EOMONTH(G17,1) -> 44408 | I17: =EOMONTH(H17,1) -> 44439 | J17: =EOMONTH(I17,1) -> 44469 | K17: =EOMONTH(J17,1) -> 44500 | L17: =EOMONTH(K17,1) -> 44530 | M17: =EOMONTH(L17,1) -> 44561 | ... AC17: =EOMONTH(AB17,1) -> 45046
B18: VENTA | E18: ='Cost Planning'!H44+'Cost Planning'!H62+'Cost Planning'!H78 -> 0 | F18: ='Cost Planning'!I44+'Cost Planning'!I62+'Cost Planning'!I78 -> 0 | G18: ='Cost Planning'!J44+'Cost Planning'!J62+'Cost Planning'!J78 -> 0 | H18: ='Cost Planning'!K44+'Cost Planning'!K62+'Cost Planning'!K78 -> 0 | I18: ='Cost Planning'!L44+'Cost Planning'!L62+'Cost Planning'!L78 -> 0 | J18: ='Cost Planning'!M44+'Cost Planning'!M62+'Cost Planning'!M78 -> 0 | K18: ='Cost Planning'!N44+'Cost Planning'!N62+'Cost Planning'!N78 -> 0 | L18: ='Cost Planning'!O44+'Cost Planning'!O62+'Cost Planning'!O78 -> 0 | ... AC18: ='Cost Planning'!AF44+'Cost Planning'!AF62+'Cost Planning'!AF78 -> 0
B19: HORAS | E19: =E31-D31 -> 0 | F19: =F31-E31 -> 0 | G19: =G31-F31 -> 0 | H19: =H31-G31 -> 0 | I19: =I31-H31 -> 0 | J19: =J31-I31 -> 0 | K19: =K31-J31 -> 0 | L19: =L31-K31 -> 0 | ... AC19: =AC31-AB31 -> 0
B20: - COSTE RECURSOS | E20: =E32-D32 -> 0 | F20: =F32-E32 -> 0 | G20: =G32-F32 -> 0 | H20: =H32-G32 -> 0 | I20: =I32-H32 -> 0 | J20: =J32-I32 -> 0 | K20: =K32-J32 -> 0 | L20: =L32-K32 -> 0 | ... AC20: =AC32-AB32 -> 0
B21: - RIESGOS | E21: =E33-D33 -> 0 | F21: =F33-E33 -> 0 | G21: =G33-F33 -> 0 | H21: =H33-G33 -> 0 | I21: =I33-H33 -> 0 | J21: =J33-I33 -> 0 | K21: =K33-J33 -> 0 | L21: =L33-K33 -> 0 | ... AC21: =AC33-AB33 -> 0
B22: - GARANTIA | E22: =E34-D34 -> 0 | F22: =F34-E34 -> 0 | G22: =G34-F34 -> 0 | H22: =H34-G34 -> 0 | I22: =I34-H34 -> 0 | J22: =J34-I34 -> 0 | K22: =K34-J34 -> 0 | L22: =L34-K34 -> 0 | ... AC22: =AC34-AB34 -> 0
B23: - GASTOS | E23: =E35-D35 -> 0 | F23: =F35-E35 -> 0 | G23: =G35-F35 -> 0 | H23: =H35-G35 -> 0 | I23: =I35-H35 -> 0 | J23: =J35-I35 -> 0 | K23: =K35-J35 -> 0 | L23: =L35-K35 -> 0 | ... AC23: =AC35-AB35 -> 0
B24: - COMPRAS | E24: =E36-D36 -> 1000 | F24: =F36-E36 -> 0 | G24: =G36-F36 -> 0 | H24: =H36-G36 -> 0 | I24: =I36-H36 -> 0 | J24: =J36-I36 -> 0 | K24: =K36-J36 -> 0 | L24: =L36-K36 -> 0 | ... AC24: =AC36-AB36 -> 0
B25: COSTE DIRECTO | E25: =SUM(E20:E24) -> 1000 | F25: =SUM(F20:F24) -> 0 | G25: =SUM(G20:G24) -> 0 | H25: =SUM(H20:H24) -> 0 | I25: =SUM(I20:I24) -> 0 | J25: =SUM(J20:J24) -> 0 | K25: =SUM(K20:K24) -> 0 | L25: =SUM(L20:L24) -> 0 | ... AC25: =SUM(AC20:AC24) -> 0
B26: MARGEN DIRECTO (euros) | E26: =E18-E25 -> -1000 | F26: =F18-F25 -> 0 | G26: =G18-G25 -> 0 | H26: =H18-H25 -> 0 | I26: =I18-I25 -> 0 | J26: =J18-J25 -> 0 | K26: =K18-K25 -> 0 | L26: =L18-L25 -> 0 | ... AC26: =AC18-AC25 -> 0
B27: MARGEN DIRECTO (%) | E27: =IF(E18=0,0,(E18-SUM(E20,E21,E22,E23,E24))/E18) -> 0 | F27: =IF(F18=0,0,(F18-SUM(F20,F21,F22,F23,F24))/F18) -> 0 | G27: =IF(G18=0,0,(G18-SUM(G20,G21,G22,G23,G24))/G18) -> 0 | H27: =IF(H18=0,0,(H18-SUM(H20,H21,H22,H23,H24))/H18) -> 0 | I27: =IF(I18=0,0,(I18-SUM(I20,I21,I22,I23,I24))/I18) -> 0 | J27: =IF(J18=0,0,(J18-SUM(J20,J21,J22,J23,J24))/J18) -> 0 | K27: =IF(K18=0,0,(K18-SUM(K20,K21,K22,K23,K24))/K18) -> 0 | L27: =IF(L18=0,0,(L18-SUM(L20,L21,L22,L23,L24))/L18) -> 0 | ... AC27: =IF(AC18=0,0,(AC18-SUM(AC20,AC21,AC22,AC23,AC24))/AC18) -> 0
B29: REALIZADO + PREVISTO ACUMULADO | D29: ANTERIOR | E29: ='Project Infor'!C8 -> 44287 | F29: =EOMONTH(E29,1) -> 44347 | G29: =EOMONTH(F29,1) -> 44377 | H29: =EOMONTH(G29,1) -> 44408 | I29: =EOMONTH(H29,1) -> 44439 | J29: =EOMONTH(I29,1) -> 44469 | K29: =EOMONTH(J29,1) -> 44500 | L29: =EOMONTH(K29,1) -> 44530 | M29: =EOMONTH(L29,1) -> 44561 | ... AC29: =EOMONTH(AB29,1) -> 45046
B30: VENTA ACUMULADA | D30: ='Project Infor'!C45 -> 0 | E30: =IF(E40,E40,D30+E18) -> 0 | F30: =IF(F40,F40,E30+F18) -> 0 | G30: =IF(G40,G40,F30+G18) -> 0 | H30: =IF(H40,H40,G30+H18) -> 0 | I30: =IF(I40,I40,H30+I18) -> 0 | J30: =IF(J40,J40,I30+J18) -> 0 | K30: =IF(K40,K40,J30+K18) -> 0 | L30: =IF(L40,L40,K30+L18) -> 0 | ... AC30: =IF(AC40,AC40,AB30+AC18) -> 0
B31: HORAS | D31: ='Project Infor'!C46 -> 0 | E31: =D31+LOOKUP(E$5,'Cost Planning'!$H$8:$AF$8,'Cost Planning'!$H$9:$AF$9) -> 0 | F31: =E31+LOOKUP(F$5,'Cost Planning'!$H$8:$AF$8,'Cost Planning'!$H$9:$AF$9) -> 0 | G31: =F31+LOOKUP(G$5,'Cost Planning'!$H$8:$AF$8,'Cost Planning'!$H$9:$AF$9) -> 0 | H31: =G31+LOOKUP(H$5,'Cost Planning'!$H$8:$AF$8,'Cost Planning'!$H$9:$AF$9) -> 0 | I31: =H31+LOOKUP(I$5,'Cost Planning'!$H$8:$AF$8,'Cost Planning'!$H$9:$AF$9) -> 0 | J31: =I31+LOOKUP(J$5,'Cost Planning'!$H$8:$AF$8,'Cost Planning'!$H$9:$AF$9) -> 0 | K31: =J31+LOOKUP(K$5,'Cost Planning'!$H$8:$AF$8,'Cost Planning'!$H$9:$AF$9) -> 0 | L31: =K31+LOOKUP(L$5,'Cost Planning'!$H$8:$AF$8,'Cost Planning'!$H$9:$AF$9) -> 0 | ... AC31: =AB31+LOOKUP(AC$5,'Cost Planning'!$H$8:$AF$8,'Cost Planning'!$H$9:$AF$9) -> 0
B32: - COSTE RECURSOS ACUMULADO | D32: ='Project Infor'!C47 -> 0 | E32: =D32+LOOKUP(E$5,'Cost Planning'!$H$8:$AF$8,'Cost Planning'!$H$40:$AF$40)+LOOKUP(E$5,'Cost Planning'!$H$8:$AF$8,'Cost Planning'!$H$41:$AF$41) -> 0 | F32: =E32+LOOKUP(F$5,'Cost Planning'!$H$8:$AF$8,'Cost Planning'!$H$40:$AF$40)+LOOKUP(F$5,'Cost Planning'!$H$8:$AF$8,'Cost Planning'!$H$41:$AF$41) -> 0 | G32: =F32+LOOKUP(G$5,'Cost Planning'!$H$8:$AF$8,'Cost Planning'!$H$40:$AF$40)+LOOKUP(G$5,'Cost Planning'!$H$8:$AF$8,'Cost Planning'!$H$41:$AF$41) -> 0 | H32: =G32+LOOKUP(H$5,'Cost Planning'!$H$8:$AF$8,'Cost Planning'!$H$40:$AF$40)+LOOKUP(H$5,'Cost Planning'!$H$8:$AF$8,'Cost Planning'!$H$41:$AF$41) -> 0 | I32: =H32+LOOKUP(I$5,'Cost Planning'!$H$8:$AF$8,'Cost Planning'!$H$40:$AF$40)+LOOKUP(I$5,'Cost Planning'!$H$8:$AF$8,'Cost Planning'!$H$41:$AF$41) -> 0 | J32: =I32+LOOKUP(J$5,'Cost Planning'!$H$8:$AF$8,'Cost Planning'!$H$40:$AF$40)+LOOKUP(J$5,'Cost Planning'!$H$8:$AF$8,'Cost Planning'!$H$41:$AF$41) -> 0 | K32: =J32+LOOKUP(K$5,'Cost Planning'!$H$8:$AF$8,'Cost Planning'!$H$40:$AF$40)+LOOKUP(K$5,'Cost Planning'!$H$8:$AF$8,'Cost Planning'!$H$41:$AF$41) -> 0 | L32: =K32+LOOKUP(L$5,'Cost Planning'!$H$8:$AF$8,'Cost Planning'!$H$40:$AF$40)+LOOKUP(L$5,'Cost Planning'!$H$8:$AF$8,'Cost Planning'!$H$41:$AF$41) -> 0 | ... AC32: =AB32+LOOKUP(AC$5,'Cost Planning'!$H$8:$AF$8,'Cost Planning'!$H$40:$AF$40)+LOOKUP(AC$5,'Cost Planning'!$H$8:$AF$8,'Cost Planning'!$H$41:$AF$41) -> 0
B33: - RIESGOS | E33: =D33+LOOKUP(E$5,'Cost Planning'!$H$8:$AF$8,'Cost Planning'!$H$47:$AF$47) -> 0 | F33: =E33+LOOKUP(F$5,'Cost Planning'!$H$8:$AF$8,'Cost Planning'!$H$47:$AF$47) -> 0 | G33: =F33+LOOKUP(G$5,'Cost Planning'!$H$8:$AF$8,'Cost Planning'!$H$47:$AF$47) -> 0 | H33: =G33+LOOKUP(H$5,'Cost Planning'!$H$8:$AF$8,'Cost Planning'!$H$47:$AF$47) -> 0 | I33: =H33+LOOKUP(I$5,'Cost Planning'!$H$8:$AF$8,'Cost Planning'!$H$47:$AF$47) -> 0 | J33: =I33+LOOKUP(J$5,'Cost Planning'!$H$8:$AF$8,'Cost Planning'!$H$47:$AF$47) -> 0 | K33: =J33+LOOKUP(K$5,'Cost Planning'!$H$8:$AF$8,'Cost Planning'!$H$47:$AF$47) -> 0 | L33: =K33+LOOKUP(L$5,'Cost Planning'!$H$8:$AF$8,'Cost Planning'!$H$47:$AF$47) -> 0 | ... AC33: =AB33+LOOKUP(AC$5,'Cost Planning'!$H$8:$AF$8,'Cost Planning'!$H$47:$AF$47) -> 0
B34: - GARANTIA | E34: =D34+LOOKUP(E$5,'Cost Planning'!$H$8:$AF$8,'Cost Planning'!$H$48:$AF$48) -> 0 | F34: =E34+LOOKUP(F$5,'Cost Planning'!$H$8:$AF$8,'Cost Planning'!$H$48:$AF$48) -> 0 | G34: =F34+LOOKUP(G$5,'Cost Planning'!$H$8:$AF$8,'Cost Planning'!$H$48:$AF$48) -> 0 | H34: =G34+LOOKUP(H$5,'Cost Planning'!$H$8:$AF$8,'Cost Planning'!$H$48:$AF$48) -> 0 | I34: =H34+LOOKUP(I$5,'Cost Planning'!$H$8:$AF$8,'Cost Planning'!$H$48:$AF$48) -> 0 | J34: =I34+LOOKUP(J$5,'Cost Planning'!$H$8:$AF$8,'Cost Planning'!$H$48:$AF$48) -> 0 | K34: =J34+LOOKUP(K$5,'Cost Planning'!$H$8:$AF$8,'Cost Planning'!$H$48:$AF$48) -> 0 | L34: =K34+LOOKUP(L$5,'Cost Planning'!$H$8:$AF$8,'Cost Planning'!$H$48:$AF$48) -> 0 | ... AC34: =AB34+LOOKUP(AC$5,'Cost Planning'!$H$8:$AF$8,'Cost Planning'!$H$48:$AF$48) -> 0
B35: - GASTOS | D35: ='Project Infor'!C48 -> 0 | E35: =D35+LOOKUP(E$5,'Cost Planning'!$H$8:$AF$8,'Cost Planning'!$H$61:$AF$61) -> 0 | F35: =E35+LOOKUP(F$5,'Cost Planning'!$H$8:$AF$8,'Cost Planning'!$H$61:$AF$61) -> 0 | G35: =F35+LOOKUP(G$5,'Cost Planning'!$H$8:$AF$8,'Cost Planning'!$H$61:$AF$61) -> 0 | H35: =G35+LOOKUP(H$5,'Cost Planning'!$H$8:$AF$8,'Cost Planning'!$H$61:$AF$61) -> 0 | I35: =H35+LOOKUP(I$5,'Cost Planning'!$H$8:$AF$8,'Cost Planning'!$H$61:$AF$61) -> 0 | J35: =I35+LOOKUP(J$5,'Cost Planning'!$H$8:$AF$8,'Cost Planning'!$H$61:$AF$61) -> 0 | K35: =J35+LOOKUP(K$5,'Cost Planning'!$H$8:$AF$8,'Cost Planning'!$H$61:$AF$61) -> 0 | L35: =K35+LOOKUP(L$5,'Cost Planning'!$H$8:$AF$8,'Cost Planning'!$H$61:$AF$61) -> 0 | ... AC35: =AB35+LOOKUP(AC$5,'Cost Planning'!$H$8:$AF$8,'Cost Planning'!$H$61:$AF$61) -> 0
B36: - COMPRAS | D36: ='Project Infor'!C49 -> 0 | E36: =D36+LOOKUP(E$5,'Cost Planning'!$H$8:$AF$8,'Cost Planning'!$H$77:$AF$77) -> 1000 | F36: =E36+LOOKUP(F$5,'Cost Planning'!$H$8:$AF$8,'Cost Planning'!$H$77:$AF$77) -> 1000 | G36: =F36+LOOKUP(G$5,'Cost Planning'!$H$8:$AF$8,'Cost Planning'!$H$77:$AF$77) -> 1000 | H36: =G36+LOOKUP(H$5,'Cost Planning'!$H$8:$AF$8,'Cost Planning'!$H$77:$AF$77) -> 1000 | I36: =H36+LOOKUP(I$5,'Cost Planning'!$H$8:$AF$8,'Cost Planning'!$H$77:$AF$77) -> 1000 | J36: =I36+LOOKUP(J$5,'Cost Planning'!$H$8:$AF$8,'Cost Planning'!$H$77:$AF$77) -> 1000 | K36: =J36+LOOKUP(K$5,'Cost Planning'!$H$8:$AF$8,'Cost Planning'!$H$77:$AF$77) -> 1000 | L36: =K36+LOOKUP(L$5,'Cost Planning'!$H$8:$AF$8,'Cost Planning'!$H$77:$AF$77) -> 1000 | ... AC36: =AB36+LOOKUP(AC$5,'Cost Planning'!$H$8:$AF$8,'Cost Planning'!$H$77:$AF$77) -> 1000
B37: COSTE DIRECTO | D37: =SUM(D32:D36) -> 0 | E37: =SUM(E32:E36) -> 1000 | F37: =SUM(F32:F36) -> 1000 | G37: =SUM(G32:G36) -> 1000 | H37: =SUM(H32:H36) -> 1000 | I37: =SUM(I32:I36) -> 1000 | J37: =SUM(J32:J36) -> 1000 | K37: =SUM(K32:K36) -> 1000 | ... AC37: =SUM(AC32:AC36) -> 1000
B38: MARGEN DIRECTO ACUMULADO (euros) | D38: =D30-D32-D33-D34-D35-D36 -> 0 | E38: =E30-E32-E33-E34-E35-E36 -> -1000 | F38: =F30-F32-F33-F34-F35-F36 -> -1000 | G38: =G30-G32-G33-G34-G35-G36 -> -1000 | H38: =H30-H32-H33-H34-H35-H36 -> -1000 | I38: =I30-I32-I33-I34-I35-I36 -> -1000 | J38: =J30-J32-J33-J34-J35-J36 -> -1000 | K38: =K30-K32-K33-K34-K35-K36 -> -1000 | ... AC38: =AC30-AC32-AC33-AC34-AC35-AC36 -> -1000
B40: VENTA ACUMULADA REPORTADA SAP | E40: =IF(OFFSET(E4,0,1)="Fin",E6) -> FALSE | F40: =IF(OFFSET(F4,0,1)="Fin",F6) -> FALSE | G40: =IF(OFFSET(G4,0,1)="Fin",G6) -> FALSE | H40: =IF(OFFSET(H4,0,1)="Fin",H6) -> FALSE | I40: =IF(OFFSET(I4,0,1)="Fin",I6) -> FALSE | J40: =IF(OFFSET(J4,0,1)="Fin",J6) -> FALSE | K40: =IF(OFFSET(K4,0,1)="Fin",K6) -> FALSE | L40: =IF(OFFSET(L4,0,1)="Fin",L6) -> FALSE | ... AC40: =IF(OFFSET(AC4,0,1)="Fin",AC6) -> FALSE
B42: FACTURACION EMITIDA/PLANIFICADA | D42: ='Project Infor'!C54 -> 0
B43: FACTURACION ACUMULADA | D43: =D42 -> 0 | E43: =E42+D43 -> 0 | F43: =F42+E43 -> 0 | G43: =G42+F43 -> 0 | H43: =H42+G43 -> 0 | I43: =I42+H43 -> 0 | J43: =J42+I43 -> 0 | K43: =K42+J43 -> 0 | L43: =L42+K43 -> 0 | ... AC43: =AC42+AB43 -> 0
B44: FACTURACION vs VENTA | E44: =E43-E30 -> 0 | F44: =F43-F30 -> 0 | G44: =G43-G30 -> 0 | H44: =H43-H30 -> 0 | I44: =I43-I30 -> 0 | J44: =J43-J30 -> 0 | K44: =K43-K30 -> 0 | L44: =L43-L30 -> 0 | ... AC44: =AC43-AC30 -> 0

Sheet Cost Summary
B2: WBS-Element | C2: ='Project Infor'!C10 -> ZEZ-AT00001-1001 | D2: ='Project Infor'!C11 -> Asistencia técnica para desarrollo Java/.Net/…
D5: PEDIDO IMPORTE NETO | E5: COSTE RECURSOS | F5: HORAS | G5: RIESGOS | H5: GARANTÍA | I5: GASTOS | J5: COMPRAS | K5: COSTE DIRECTO | L5: MARGEN DIRECTO (euros) | M5: MARGEN DIRECTO (%) | N5: MARGEN BRUTO
B6: LINEA BASE INICIAL | D6: ='Cost Overview'!F12 -> 0 | E6: ='Cost Overview'!G12 -> 0 | F6: ='Cost Overview'!H12 -> 0 | G6: ='Cost Overview'!I12 -> 0 | H6: ='Cost Overview'!J12 -> 0 | I6: ='Cost Overview'!K12 -> 0 | J6: ='Cost Overview'!L12 -> 0 | K6: =SUM(E6,G6,H6,I6,J6) -> 0 | L6: =D6-K6 -> 0 | M6: =IF(D6=0,0,(D6-E6-H6-I6-G6-J6)/D6) -> 0 | N6: =IF(D6=0,0,(D6-E6/UTILIZACION-G6/UTILIZACION-H6/UTILIZACION-I6-J6)/D6) -> 0
B7: LINEA BASE ACTUAL | D7: ='Cost Overview'!F8 -> 0 | E7: ='Cost Overview'!G8 -> 0 | F7: ='Cost Overview'!H8 -> 0 | G7: ='Cost Overview'!I8 -> 0 | H7: ='Cost Overview'!J8 -> 0 | I7: ='Cost Overview'!K8 -> 0 | J7: ='Cost Overview'!L8 -> 0 | K7: =SUM(E7,G7,H7,I7,J7) -> 0 | L7: =D7-K7 -> 0 | M7: =IF(D7=0,0,(D7-E7-H7-I7-G7-J7)/D7) -> 0 | N7: =IF(D7=0,0,(D7-E7/UTILIZACION-G7/UTILIZACION-H7/UTILIZACION-I7-J7)/D7) -> 0
B8: PROYECCIÓN PROYECTO (REAL + ESTIMADO) | D8: =D7 -> 0 | E8: =SUM('Cost Planning'!F40:AF41) -> 0 | F8: =SUM('Cost Planning'!F9:AF9) -> 0 | G8: =SUM('Cost Planning'!H47:AF47) -> 0 | H8: =SUM('Cost Planning'!H48:AF48) -> 0 | I8: =SUM('Cost Planning'!F61:AF61) -> 0 | J8: =SUM('Cost Planning'!F77:AF77) -> 1000 | K8: =SUM(E8,G8,H8,I8,J8) -> 1000 | L8: =D8-K8 -> -1000 | M8: =IF(D8=0,0,(D8-E8-H8-I8-G8-J8)/D8) -> 0 | N8: =IF(D8=0,0,(D8-E8/UTILIZACION-G8/UTILIZACION-H8/UTILIZACION-I8-J8)/D8) -> 0
B9: Diferencia de PROYECCION DEL PROYECTO con BASELINE ACTUAL | D9: =IF(D8=0,1,(D8-D7)/D8) -> 1 | E9: =IF(E8=0,1,(E8-E7)/E8) -> 1 | F9: =IF(F8=0,1,(F8-F7)/F8) -> 1 | G9: =IF(G8=0,1,(G8-G7)/G8) -> 1 | H9: =IF(H8=0,1,(H8-H7)/H8) -> 1 | I9: =IF(I8=0,1,(I8-I7)/I8) -> 1 | J9: =IF(J8=0,1,(J8-J7)/J8) -> 1 | K9: =IF(K8=0,1,(K8-K7)/K8) -> 1 | L9: =IF(L8=0,1,(L8-L7)/L8) -> 1 | M9: =M8-M7 -> 0
B11: REALIZADO | D11: =SUMIF('Monthly View'!$E$4:$AC$4,"Real",'Monthly View'!$E$18:$AC$18)+'Project Infor'!C45 -> 0 | E11: =SUMIF('Monthly View'!$E$4:$AC$4,"Real",'Monthly View'!$E$20:$AC$20)+'Project Infor'!C47 -> 0 | F11: =SUMIF('Monthly View'!$E$4:$AC$4,"Real",'Monthly View'!$E$19:$AC$19)+'Project Infor'!C46 -> 0 | G11: =SUMIF('Monthly View'!$E$4:$AC$4,"Real",'Monthly View'!$E$21:$AC$21) -> 0 | H11: =SUMIF('Monthly View'!$E$4:$AC$4,"Real",'Monthly View'!$E$22:$AC$22) -> 0 | I11: =SUMIF('Monthly View'!$E$4:$AC$4,"Real",'Monthly View'!$E$23:$AC$23)+'Project Infor'!C48 -> 0 | J11: =SUMIF('Monthly View'!$E$4:$AC$4,"Real",'Monthly View'!$E$24:$AC$24)+'Project Infor'!C49 -> 1000 | K11: =SUM(E11,G11,H11,I11,J11) -> 1000 | L11: =D11-K11 -> -1000 | M11: =IF(D11=0,0,(D11-E11-H11-I11-G11-J11)/D11) -> 0 | N11: =IF(D11=0,0,(D11-E11/UTILIZACION-G11/UTILIZACION-H11/UTILIZACION-I11-J11)/D11) -> 0
B12: % Avance | D12: =IF(D11=0,1,(D11/D8)) -> 1 | E12: =IF(E11=0,1,(E11/E8)) -> 1 | F12: =IF(F11=0,1,(F11/F8)) -> 1
B14: (!) La VENTA total planificada excede el PEDIDO | F14: ='Cost Planning'!N5 -> 0
B17: Comentarios adicionales Cost Summary
B18: <dd/mm/aaaa> comentario <dd/mm/aaaa> comentario <dd/mm/aaaa> comentario

Sheet Ayuda
B2: CORE PC - VENTA POR AVANCE DE COSTES
B4: Pasos para completar el CORE en la apertura de un proyecto
B5: 1) Completar "Project Infor" incluyendo los datos del PPO
B6: 2) Revisar "Cost Overview" con la información de la Baseline Inicial (Fila 10) para que esté ok con PPO
B7: 3) Completar los coste del personal que va a ejecutar el proyecto en "Resources". IMPORTANTE: No indicar Nombre y Apellidos, solo Iniciales. También se debe indicar para cada perfil si es o no INTERCO porque ese dato se utiliza para calcular en coste de cada tipo de perfil y si no se completa no se tiene en cuenta el coste.
B8: 4) Completar el Planning de Horas, Riesgos, Garantía, Gastos y Compras en "Cost Planning". Tendremos avisos sobre lo que no hayamos planificado en cada una de las secciones
B9: 5) En "Monthly View" y "Cost Summary" tendremos la información de arranque del proyecto
B11: Pasos para completar la información mensual
B12: 1) Introducir la Fecha de Reporting en "Project Infor", celda C8
B13: 2) Introducir Ampliaciones y Reestimaciones en "Cost Overview"
B14: 3) Actualizar Costes de Recursos en "Resources". Importante: como nuestros costes puede que no cuadren 100% con los de SAP, si tenemos el dato de los costes mensuales del mes pasado en SAP, metemos la diferencia en "Cost Planning" en las celdas amarillas. Así vamos corrigiendo las diferencias mes a mes. Si la diferencia es signiticativa tendremos que revisar los costes de los recursos por si alguno no está como en SAP. Tambien en Resources tenemos que actualizar la tarifa de venta, ya sea por hora o por jornadas
B15: 4) Actualizar el Planning de Horas Reales y Facturables, Riesgos, Garantía, Gastos y Compras en "Cost Planning". Tendremos avisos sobre lo que no hayamos planificado en cada una de las secciones. Si por ejemplo nos vamos a gastar más en Horas y queremos reestimar Riesgos, tendremos que volver a la pestaña "Cost Overview" para ver qué reestimación sería necesaria. Las Reestimaciones tienen que tener validación por parte de Cost Control & Optimization (CCO).
... B25: Los datos del FORECAST de VENTA aparecen en "Monthly View" - Fila 18. En la pestaña Aux Forecast se puede ir guardando el forecast proporcionado cada mes para tener una vista de la evolución de Forecast.

Sheet aux Billing Plan
B2: WBS-Element | C2: ='Project Infor'!C10 -> ZEZ-AT00001-1001 | D2: ='Project Infor'!C11 -> Asistencia técnica para desarrollo Java/.Net/…
B5: IMPORTE NETO A FACTURAR | E5: ='Cost Overview'!F8 -> 0 | F5: (!) Faltan HITOS de FACTURACION por planificar | J5: =E5-F41 -> 0
B7: TIPO FACTURA | C7: FECHA ESTIMADA FACTURA | D7: DCat | E7: CONCEPTO FACTURA | F7: IMPORTE FACTURA | G7: Currency | H7: IMPUESTOS (%) | I7: IMPORTE más IMPUESTOS | J7: LINEA/S DE PEDIDO | K7: CLIENTE | L7: Ticket support BILLING & COLLECTION | M7: FECHA FACTURA | N7: ENVIO FACTURA | O7: OTRA INFOR FACTURACION | P7: COBRADA
D8: =IF(C8=0," ","Z2") | I8: =IF(F8=0," ",F8+F8*H8)
D9: =IF(C9=0," ","Z2") | I9: =IF(F9=0," ",F9+F9*H9)
D10: =IF(C10=0," ","Z2") | I10: =IF(F10=0," ",F10+F10*H10)
D11: =IF(C11=0," ","Z2") | I11: =IF(F11=0," ",F11+F11*H11)
D12: =IF(C12=0," ","Z2") | I12: =IF(F12=0," ",F12+F12*H12)
D13: =IF(C13=0," ","Z2") | I13: =IF(F13=0," ",F13+F13*H13)
D14: =IF(C14=0," ","Z2") | I14: =IF(F14=0," ",F14+F14*H14)
D15: =IF(C15=0," ","Z2") | I15: =IF(F15=0," ",F15+F15*H15)
D16: =IF(C16=0," ","Z2") | I16: =IF(F16=0," ",F16+F16*H16)
D17: =IF(C17=0," ","Z2") | I17: =IF(F17=0," ",F17+F17*H17)
D18: =IF(C18=0," ","Z2") | I18: =IF(F18=0," ",F18+F18*H18)
D19: =IF(C19=0," ","Z2") | I19: =IF(F19=0," ",F19+F19*H19)
... D40: =IF(C40=0," ","Z2") | I40: =IF(F40=0," ",F40+F40*H40)
B41: TOTAL FACTURACION | F41: =SUM(F8:F40) -> 0 | I41: =SUM(I8:I40) -> 0
B50: Comentarios adicionales Billing Plan
B51: <dd/mm/aaaa> comentario <dd/mm/aaaa> comentario <dd/mm/aaaa> comentario

Sheet aux Forecast
B2: WBS-Element | C2: ='Project Infor'!C10 -> ZEZ-AT00001-1001 | D2: ='Project Infor'!C11 -> Asistencia técnica para desarrollo Java/.Net/…
B4: Mes Forecast | C4: 44197 | D4: =EOMONTH(C4,1) -> 44255 | E4: =EOMONTH(D4,1) -> 44286 | F4: =EOMONTH(E4,1) -> 44316 | G4: =EOMONTH(F4,1) -> 44347 | H4: =EOMONTH(G4,1) -> 44377 | I4: =EOMONTH(H4,1) -> 44408 | J4: =EOMONTH(I4,1) -> 44439 | K4: =EOMONTH(J4,1) -> 44469 | ... Z4: =EOMONTH(Y4,1) -> 44926
B5: 44197
B6: =EOMONTH(B5,1) -> 44255
B7: =EOMONTH(B6,1) -> 44286
B8: =EOMONTH(B7,1) -> 44316
B9: =EOMONTH(B8,1) -> 44347
B10: =EOMONTH(B9,1) -> 44377
B11: =EOMONTH(B10,1) -> 44408
B12: =EOMONTH(B11,1) -> 44439
B13: =EOMONTH(B12,1) -> 44469
B14: =EOMONTH(B13,1) -> 44500
B15: =EOMONTH(B14,1) -> 44530
B16: =EOMONTH(B15,1) -> 44561
B19: Comentarios adicionales Forecast
B20: <dd/mm/aaaa> comentario <dd/mm/aaaa> comentario <dd/mm/aaaa> comentario

Sheet aux UTE
B2: WBS-Element | C2: ='Project Infor'!C10 -> ZEZ-AT00001-1001 | D2: ='Project Infor'!C11 -> Asistencia técnica para desarrollo Java/.Net/…
B4: CLIENTE | C4: MINISTERIO | F4: ENTIDADES que forman la UTE | H4: PORCENTAJE | I4: IMPORTE (sin IVA) | J4: INTERLOCUTOR | K4: INFOR ADICIONAL
B5: GERENTE UTE | C5: Nombre Apellidos | F5: Entidad 1 | H5: 0.5 | I5: 5000 | J5: Nombre Apellidos
B6: DENOMINACION UTE | C6: UTE CONNECTIS --- | F6: Entidad 2 | H6: 0.1 | I6: 1000
B7: IMPORTE CONTRATACION (SIN iva) | C7: 10000 | E7: (!) Los IMPORTES por ENTIDADES no coinciden con el TOTAL | F7: Entidad 3 | H7: 0.2 | I7: 2000
F8: Entidad 4 | H8: 0.1 | I8: 1000
F9: Entidad 5 | H9: 0.1 | I9: 1000
C10: (!) Faltan HITOS de FACTURACION por planificar
B12: TIPO FACTURA | C12: FECHA ESTIMADA FACTURA | D12: ENTIDAD que FACTURA | E12: CONCEPTO FACTURA | F12: IMPORTE FACTURA | G12: Currency | H12: IMPUESTOS (%) | I12: IMPORTE más IMPUESTOS | J12: CLIENTE | K12: ENVIADA a utes@getronics.com | L12: FECHA FACTURA | M12: ENVIO FACTURA | N12: OTRA INFOR FACTURACION | O12: COBRADA
B13: FACTURA | C13: 44286 | D13: Entidad 1 | E13: Factura Hito 1 | F13: 3000 | G13: EUR | H13: 0.21 | I13: =IF(F13=0," ",F13+F13*H13) -> 3630 | J13: MINISTERIO | M13: Portal efacturación
D14: =IF(C14=0," ","Z2") | I14: =IF(F14=0," ",F14+F14*H14)
D15: =IF(C15=0," ","Z2") | I15: =IF(F15=0," ",F15+F15*H15)
D16: =IF(C16=0," ","Z2") | I16: =IF(F16=0," ",F16+F16*H16)
D17: =IF(C17=0," ","Z2") | I17: =IF(F17=0," ",F17+F17*H17)
D18: =IF(C18=0," ","Z2") | I18: =IF(F18=0," ",F18+F18*H18)
D19: =IF(C19=0," ","Z2") | I19: =IF(F19=0," ",F19+F19*H19)
D20: =IF(C20=0," ","Z2") | I20: =IF(F20=0," ",F20+F20*H20)
D21: =IF(C21=0," ","Z2") | I21: =IF(F21=0," ",F21+F21*H21)
D22: =IF(C22=0," ","Z2") | I22: =IF(F22=0," ",F22+F22*H22)
D23: =IF(C23=0," ","Z2") | I23: =IF(F23=0," ",F23+F23*H23)
D24: =IF(C24=0," ","Z2") | I24: =IF(F24=0," ",F24+F24*H24)
D25: =IF(C25=0," ","Z2") | I25: =IF(F25=0," ",F25+F25*H25)
... D45: =IF(C45=0," ","Z2") | I45: =IF(F45=0," ",F45+F45*H45)
B46: TOTAL FACTURACION | F46: =SUM(F13:F45) -> 3000 | I46: =SUM(I13:I45) -> 3630
B55: Comentarios adicionales Gestión UTE
B56: <dd/mm/aaaa> comentario <dd/mm/aaaa> comentario <dd/mm/aaaa> comentario

Sheet aux Calendarios
B2: WBS-Element | C2: ='Project Infor'!C10 -> ZEZ-AT00001-1001 | D2: ='Project Infor'!C11 -> Asistencia técnica para desarrollo Java/.Net/…
B5: CALENDARIO 1 | D5: Descripción calendario
B6: HORAS/JORNADA | C6: HORAS JORNADA | D6: ='Project Infor'!$C$8 -> 44287 | E6: =EOMONTH(D6,1) -> 44347 | F6: =EOMONTH(E6,1) -> 44377 | G6: =EOMONTH(F6,1) -> 44408 | H6: =EOMONTH(G6,1) -> 44439 | I6: =EOMONTH(H6,1) -> 44469 | J6: =EOMONTH(I6,1) -> 44500 | K6: =EOMONTH(J6,1) -> 44530 | L6: =EOMONTH(K6,1) -> 44561 | ... AB6: =EOMONTH(AA6,1) -> 45046
B7: 8.5 | C7: =IF(B7=0,"",CONCATENATE("Jornadas de ",B7," horas: ")) -> Jornadas de 8,5 horas: | D7: 16 | E7: 16 | F7: 16 | G7: 16 | J7: 16
B8: 7 | C8: =IF(B8=0,"",CONCATENATE("Jornadas de ",B8," horas: ")) -> Jornadas de 7 horas: | D8: 3 | E8: 2 | F8: 1 | G8: 4 | H8: 22 | I8: 22 | J8: 5
B9: 6 | C9: =IF(B9=0,"",CONCATENATE("Jornadas de ",B9," horas: ")) -> Jornadas de 6 horas: | D9: 1 | E9: 3 | F9: 1 | G9: 2 | J9: 9
B10: 7.25 | C10: =IF(B10=0,"",CONCATENATE("Jornadas de ",B10," horas: ")) -> Jornadas de 7,25 horas:
B11: 5.25 | C11: =IF(B11=0,"",CONCATENATE("Jornadas de ",B11," horas: ")) -> Jornadas de 5,25 horas: | D11: 2 | F11: 2
C12: TOTAL HORAS MES | D12: =SUMPRODUCT(D7:D11,$B$7:$B$11) -> 173.5 | E12: =SUMPRODUCT(E7:E11,$B$7:$B$11) -> 168 | F12: =SUMPRODUCT(F7:F11,$B$7:$B$11) -> 159.5 | G12: =SUMPRODUCT(G7:G11,$B$7:$B$11) -> 176 | H12: =SUMPRODUCT(H7:H11,$B$7:$B$11) -> 154 | I12: =SUMPRODUCT(I7:I11,$B$7:$B$11) -> 154 | J12: =SUMPRODUCT(J7:J11,$B$7:$B$11) -> 225 | K12: =SUMPRODUCT(K7:K11,$B$7:$B$11) -> 0 | ... AB12: =SUMPRODUCT(AB7:AB11,$B$7:$B$11) -> 0
B15: CALENDARIO 2 | D15: Descripción calendario
B16: HORAS/JORNADA | C16: HORAS JORNADA | D16: ='Project Infor'!$C$8 -> 44287 | E16: =EOMONTH(D16,1) -> 44347 | F16: =EOMONTH(E16,1) -> 44377 | G16: =EOMONTH(F16,1) -> 44408 | H16: =EOMONTH(G16,1) -> 44439 | I16: =EOMONTH(H16,1) -> 44469 | J16: =EOMONTH(I16,1) -> 44500 | K16: =EOMONTH(J16,1) -> 44530 | L16: =EOMONTH(K16,1) -> 44561 | ... AB16: =EOMONTH(AA16,1) -> 45046
B17: 8 | C17: =IF(B17=0,"",CONCATENATE("Jornadas de ",B17," horas: ")) -> Jornadas de 8 horas: | D17: 16
B18: 6 | C18: =IF(B18=0,"",CONCATENATE("Jornadas de ",B18," horas: ")) -> Jornadas de 6 horas: | D18: 3
C19: =IF(B19=0,"",CONCATENATE("Jornadas de ",B19," horas: "))
C21: =IF(B21=0,"",CONCATENATE("Jornadas de ",B21," horas: "))
C22: TOTAL HORAS MES | D22: =SUMPRODUCT(D17:D21,$B$17:$B$21) -> 146 | E22: =SUMPRODUCT(E17:E21,$B$17:$B$21) -> 0 | F22: =SUMPRODUCT(F17:F21,$B$17:$B$21) -> 0 | G22: =SUMPRODUCT(G17:G21,$B$17:$B$21) -> 0 | H22: =SUMPRODUCT(H17:H21,$B$17:$B$21) -> 0 | I22: =SUMPRODUCT(I17:I21,$B$17:$B$21) -> 0 | J22: =SUMPRODUCT(J17:J21,$B$17:$B$21) -> 0 | K22: =SUMPRODUCT(K17:K21,$B$17:$B$21) -> 0 | ... AB22: =SUMPRODUCT(AB17:AB21,$B$17:$B$21) -> 0
B25: CALENDARIO 3 | D25: Descripción calendario
B26: HORAS/JORNADA | C26: HORAS JORNADA | D26: ='Project Infor'!$C$8 -> 44287 | E26: =EOMONTH(D26,1) -> 44347 | F26: =EOMONTH(E26,1) -> 44377 | G26: =EOMONTH(F26,1) -> 44408 | H26: =EOMONTH(G26,1) -> 44439 | I26: =EOMONTH(H26,1) -> 44469 | J26: =EOMONTH(I26,1) -> 44500 | K26: =EOMONTH(J26,1) -> 44530 | L26: =EOMONTH(K26,1) -> 44561 | ... AB26: =EOMONTH(AA26,1) -> 45046
B27: 7 | C27: =IF(B27=0,"",CONCATENATE("Jornadas de ",B27," horas: ")) -> Jornadas de 7 horas: | D27: 22 | E27: 20 | F27: 21 | G27: 21 | H27: 22 | I27: 22 | J27: 22 | K27: 21 | L27: 22 | M27: 16
C28: =IF(B28=0,"",CONCATENATE("Jornadas de ",B28," horas: "))
C29: =IF(B29=0,"",CONCATENATE("Jornadas de ",B29," horas: "))
C31: =IF(B31=0,"",CONCATENATE("Jornadas de ",B31," horas: "))
